2025-06-30 11:51:20,244 - ERROR - Unhandled error at http://127.0.0.1:8000/signin
Traceback (most recent call last):
  File "C:\Users\Manik\AppData\Local\Programs\Python\Python312\Lib\site-packages\sqlalchemy\dialects\postgresql\asyncpg.py", line 514, in _prepare_and_execute
    prepared_stmt, attributes = await adapt_connection._prepare(
                                ^^^^^^^^^^^^^^^^^^^^^^^^^^^^^^^^
  File "C:\Users\Manik\AppData\Local\Programs\Python\Python312\Lib\site-packages\sqlalchemy\dialects\postgresql\asyncpg.py", line 760, in _prepare
    prepared_stmt = await self._connection.prepare(
                    ^^^^^^^^^^^^^^^^^^^^^^^^^^^^^^^
  File "C:\Users\Manik\AppData\Local\Programs\Python\Python312\Lib\site-packages\asyncpg\connection.py", line 635, in prepare
    return await self._prepare(
           ^^^^^^^^^^^^^^^^^^^^
  File "C:\Users\Manik\AppData\Local\Programs\Python\Python312\Lib\site-packages\asyncpg\connection.py", line 653, in _prepare
    stmt = await self._get_statement(
           ^^^^^^^^^^^^^^^^^^^^^^^^^^
  File "C:\Users\Manik\AppData\Local\Programs\Python\Python312\Lib\site-packages\asyncpg\connection.py", line 432, in _get_statement
    statement = await self._protocol.prepare(
                ^^^^^^^^^^^^^^^^^^^^^^^^^^^^^
  File "asyncpg\\protocol\\protocol.pyx", line 165, in prepare
asyncpg.exceptions.UndefinedColumnError: column users.email does not exist

The above exception was the direct cause of the following exception:

Traceback (most recent call last):
  File "C:\Users\Manik\AppData\Local\Programs\Python\Python312\Lib\site-packages\sqlalchemy\engine\base.py", line 1967, in _exec_single_context
    self.dialect.do_execute(
  File "C:\Users\Manik\AppData\Local\Programs\Python\Python312\Lib\site-packages\sqlalchemy\engine\default.py", line 941, in do_execute
    cursor.execute(statement, parameters)
  File "C:\Users\Manik\AppData\Local\Programs\Python\Python312\Lib\site-packages\sqlalchemy\dialects\postgresql\asyncpg.py", line 572, in execute
    self._adapt_connection.await_(
  File "C:\Users\Manik\AppData\Local\Programs\Python\Python312\Lib\site-packages\sqlalchemy\util\_concurrency_py3k.py", line 132, in await_only
    return current.parent.switch(awaitable)  # type: ignore[no-any-return,attr-defined] # noqa: E501
           ^^^^^^^^^^^^^^^^^^^^^^^^^^^^^^^^
  File "C:\Users\Manik\AppData\Local\Programs\Python\Python312\Lib\site-packages\sqlalchemy\util\_concurrency_py3k.py", line 196, in greenlet_spawn
    value = await result
            ^^^^^^^^^^^^
  File "C:\Users\Manik\AppData\Local\Programs\Python\Python312\Lib\site-packages\sqlalchemy\dialects\postgresql\asyncpg.py", line 550, in _prepare_and_execute
    self._handle_exception(error)
  File "C:\Users\Manik\AppData\Local\Programs\Python\Python312\Lib\site-packages\sqlalchemy\dialects\postgresql\asyncpg.py", line 501, in _handle_exception
    self._adapt_connection._handle_exception(error)
  File "C:\Users\Manik\AppData\Local\Programs\Python\Python312\Lib\site-packages\sqlalchemy\dialects\postgresql\asyncpg.py", line 784, in _handle_exception
    raise translated_error from error
sqlalchemy.dialects.postgresql.asyncpg.AsyncAdapt_asyncpg_dbapi.ProgrammingError: <class 'asyncpg.exceptions.UndefinedColumnError'>: column users.email does not exist

The above exception was the direct cause of the following exception:

Traceback (most recent call last):
  File "C:\Users\Manik\AppData\Local\Programs\Python\Python312\Lib\site-packages\starlette\middleware\errors.py", line 165, in __call__
    await self.app(scope, receive, _send)
  File "C:\Users\Manik\AppData\Local\Programs\Python\Python312\Lib\site-packages\starlette\middleware\cors.py", line 93, in __call__
    await self.simple_response(scope, receive, send, request_headers=headers)
  File "C:\Users\Manik\AppData\Local\Programs\Python\Python312\Lib\site-packages\starlette\middleware\cors.py", line 144, in simple_response
    await self.app(scope, receive, send)
  File "C:\Users\Manik\AppData\Local\Programs\Python\Python312\Lib\site-packages\starlette\middleware\exceptions.py", line 62, in __call__
    await wrap_app_handling_exceptions(self.app, conn)(scope, receive, send)
  File "C:\Users\Manik\AppData\Local\Programs\Python\Python312\Lib\site-packages\starlette\_exception_handler.py", line 53, in wrapped_app
    raise exc
  File "C:\Users\Manik\AppData\Local\Programs\Python\Python312\Lib\site-packages\starlette\_exception_handler.py", line 42, in wrapped_app
    await app(scope, receive, sender)
  File "C:\Users\Manik\AppData\Local\Programs\Python\Python312\Lib\site-packages\starlette\routing.py", line 714, in __call__
    await self.middleware_stack(scope, receive, send)
  File "C:\Users\Manik\AppData\Local\Programs\Python\Python312\Lib\site-packages\starlette\routing.py", line 734, in app
    await route.handle(scope, receive, send)
  File "C:\Users\Manik\AppData\Local\Programs\Python\Python312\Lib\site-packages\starlette\routing.py", line 288, in handle
    await self.app(scope, receive, send)
  File "C:\Users\Manik\AppData\Local\Programs\Python\Python312\Lib\site-packages\starlette\routing.py", line 76, in app
    await wrap_app_handling_exceptions(app, request)(scope, receive, send)
  File "C:\Users\Manik\AppData\Local\Programs\Python\Python312\Lib\site-packages\starlette\_exception_handler.py", line 53, in wrapped_app
    raise exc
  File "C:\Users\Manik\AppData\Local\Programs\Python\Python312\Lib\site-packages\starlette\_exception_handler.py", line 42, in wrapped_app
    await app(scope, receive, sender)
  File "C:\Users\Manik\AppData\Local\Programs\Python\Python312\Lib\site-packages\starlette\routing.py", line 73, in app
    response = await f(request)
               ^^^^^^^^^^^^^^^^
  File "C:\Users\Manik\AppData\Local\Programs\Python\Python312\Lib\site-packages\fastapi\routing.py", line 301, in app
    raw_response = await run_endpoint_function(
                   ^^^^^^^^^^^^^^^^^^^^^^^^^^^^
  File "C:\Users\Manik\AppData\Local\Programs\Python\Python312\Lib\site-packages\fastapi\routing.py", line 212, in run_endpoint_function
    return await dependant.call(**values)
           ^^^^^^^^^^^^^^^^^^^^^^^^^^^^^^
  File "D:\chatbot_app_final\backend\main.py", line 80, in signin
    db_user = await crud.get_user_by_email(db, user.email)
              ^^^^^^^^^^^^^^^^^^^^^^^^^^^^^^^^^^^^^^^^^^^^
  File "D:\chatbot_app_final\backend\crud.py", line 37, in get_user_by_email
    result = await db.execute(select(models.User).where(models.User.email == email))
             ^^^^^^^^^^^^^^^^^^^^^^^^^^^^^^^^^^^^^^^^^^^^^^^^^^^^^^^^^^^^^^^^^^^^^^^
  File "C:\Users\Manik\AppData\Local\Programs\Python\Python312\Lib\site-packages\sqlalchemy\ext\asyncio\session.py", line 461, in execute
    result = await greenlet_spawn(
             ^^^^^^^^^^^^^^^^^^^^^
  File "C:\Users\Manik\AppData\Local\Programs\Python\Python312\Lib\site-packages\sqlalchemy\util\_concurrency_py3k.py", line 201, in greenlet_spawn
    result = context.throw(*sys.exc_info())
             ^^^^^^^^^^^^^^^^^^^^^^^^^^^^^^
  File "C:\Users\Manik\AppData\Local\Programs\Python\Python312\Lib\site-packages\sqlalchemy\orm\session.py", line 2362, in execute
    return self._execute_internal(
           ^^^^^^^^^^^^^^^^^^^^^^^
  File "C:\Users\Manik\AppData\Local\Programs\Python\Python312\Lib\site-packages\sqlalchemy\orm\session.py", line 2247, in _execute_internal
    result: Result[Any] = compile_state_cls.orm_execute_statement(
                          ^^^^^^^^^^^^^^^^^^^^^^^^^^^^^^^^^^^^^^^^
  File "C:\Users\Manik\AppData\Local\Programs\Python\Python312\Lib\site-packages\sqlalchemy\orm\context.py", line 305, in orm_execute_statement
    result = conn.execute(
             ^^^^^^^^^^^^^
  File "C:\Users\Manik\AppData\Local\Programs\Python\Python312\Lib\site-packages\sqlalchemy\engine\base.py", line 1418, in execute
    return meth(
           ^^^^^
  File "C:\Users\Manik\AppData\Local\Programs\Python\Python312\Lib\site-packages\sqlalchemy\sql\elements.py", line 515, in _execute_on_connection
    return connection._execute_clauseelement(
           ^^^^^^^^^^^^^^^^^^^^^^^^^^^^^^^^^^
  File "C:\Users\Manik\AppData\Local\Programs\Python\Python312\Lib\site-packages\sqlalchemy\engine\base.py", line 1640, in _execute_clauseelement
    ret = self._execute_context(
          ^^^^^^^^^^^^^^^^^^^^^^
  File "C:\Users\Manik\AppData\Local\Programs\Python\Python312\Lib\site-packages\sqlalchemy\engine\base.py", line 1846, in _execute_context
    return self._exec_single_context(
           ^^^^^^^^^^^^^^^^^^^^^^^^^^
  File "C:\Users\Manik\AppData\Local\Programs\Python\Python312\Lib\site-packages\sqlalchemy\engine\base.py", line 1986, in _exec_single_context
    self._handle_dbapi_exception(
  File "C:\Users\Manik\AppData\Local\Programs\Python\Python312\Lib\site-packages\sqlalchemy\engine\base.py", line 2355, in _handle_dbapi_exception
    raise sqlalchemy_exception.with_traceback(exc_info[2]) from e
  File "C:\Users\Manik\AppData\Local\Programs\Python\Python312\Lib\site-packages\sqlalchemy\engine\base.py", line 1967, in _exec_single_context
    self.dialect.do_execute(
  File "C:\Users\Manik\AppData\Local\Programs\Python\Python312\Lib\site-packages\sqlalchemy\engine\default.py", line 941, in do_execute
    cursor.execute(statement, parameters)
  File "C:\Users\Manik\AppData\Local\Programs\Python\Python312\Lib\site-packages\sqlalchemy\dialects\postgresql\asyncpg.py", line 572, in execute
    self._adapt_connection.await_(
  File "C:\Users\Manik\AppData\Local\Programs\Python\Python312\Lib\site-packages\sqlalchemy\util\_concurrency_py3k.py", line 132, in await_only
    return current.parent.switch(awaitable)  # type: ignore[no-any-return,attr-defined] # noqa: E501
           ^^^^^^^^^^^^^^^^^^^^^^^^^^^^^^^^
  File "C:\Users\Manik\AppData\Local\Programs\Python\Python312\Lib\site-packages\sqlalchemy\util\_concurrency_py3k.py", line 196, in greenlet_spawn
    value = await result
            ^^^^^^^^^^^^
  File "C:\Users\Manik\AppData\Local\Programs\Python\Python312\Lib\site-packages\sqlalchemy\dialects\postgresql\asyncpg.py", line 550, in _prepare_and_execute
    self._handle_exception(error)
  File "C:\Users\Manik\AppData\Local\Programs\Python\Python312\Lib\site-packages\sqlalchemy\dialects\postgresql\asyncpg.py", line 501, in _handle_exception
    self._adapt_connection._handle_exception(error)
  File "C:\Users\Manik\AppData\Local\Programs\Python\Python312\Lib\site-packages\sqlalchemy\dialects\postgresql\asyncpg.py", line 784, in _handle_exception
    raise translated_error from error
sqlalchemy.exc.ProgrammingError: (sqlalchemy.dialects.postgresql.asyncpg.ProgrammingError) <class 'asyncpg.exceptions.UndefinedColumnError'>: column users.email does not exist
[SQL: SELECT users.id, users.email, users.password 
FROM users 
WHERE users.email = $1::VARCHAR]
[parameters: ('mj5@gmail.com',)]
(Background on this error at: https://sqlalche.me/e/20/f405)

2025-06-30 11:51:30,422 - ERROR - Unhandled error at http://127.0.0.1:8000/signup
Traceback (most recent call last):
  File "C:\Users\Manik\AppData\Local\Programs\Python\Python312\Lib\site-packages\sqlalchemy\dialects\postgresql\asyncpg.py", line 514, in _prepare_and_execute
    prepared_stmt, attributes = await adapt_connection._prepare(
                                ^^^^^^^^^^^^^^^^^^^^^^^^^^^^^^^^
  File "C:\Users\Manik\AppData\Local\Programs\Python\Python312\Lib\site-packages\sqlalchemy\dialects\postgresql\asyncpg.py", line 760, in _prepare
    prepared_stmt = await self._connection.prepare(
                    ^^^^^^^^^^^^^^^^^^^^^^^^^^^^^^^
  File "C:\Users\Manik\AppData\Local\Programs\Python\Python312\Lib\site-packages\asyncpg\connection.py", line 635, in prepare
    return await self._prepare(
           ^^^^^^^^^^^^^^^^^^^^
  File "C:\Users\Manik\AppData\Local\Programs\Python\Python312\Lib\site-packages\asyncpg\connection.py", line 653, in _prepare
    stmt = await self._get_statement(
           ^^^^^^^^^^^^^^^^^^^^^^^^^^
  File "C:\Users\Manik\AppData\Local\Programs\Python\Python312\Lib\site-packages\asyncpg\connection.py", line 432, in _get_statement
    statement = await self._protocol.prepare(
                ^^^^^^^^^^^^^^^^^^^^^^^^^^^^^
  File "asyncpg\\protocol\\protocol.pyx", line 165, in prepare
asyncpg.exceptions.UndefinedColumnError: column users.email does not exist

The above exception was the direct cause of the following exception:

Traceback (most recent call last):
  File "C:\Users\Manik\AppData\Local\Programs\Python\Python312\Lib\site-packages\sqlalchemy\engine\base.py", line 1967, in _exec_single_context
    self.dialect.do_execute(
  File "C:\Users\Manik\AppData\Local\Programs\Python\Python312\Lib\site-packages\sqlalchemy\engine\default.py", line 941, in do_execute
    cursor.execute(statement, parameters)
  File "C:\Users\Manik\AppData\Local\Programs\Python\Python312\Lib\site-packages\sqlalchemy\dialects\postgresql\asyncpg.py", line 572, in execute
    self._adapt_connection.await_(
  File "C:\Users\Manik\AppData\Local\Programs\Python\Python312\Lib\site-packages\sqlalchemy\util\_concurrency_py3k.py", line 132, in await_only
    return current.parent.switch(awaitable)  # type: ignore[no-any-return,attr-defined] # noqa: E501
           ^^^^^^^^^^^^^^^^^^^^^^^^^^^^^^^^
  File "C:\Users\Manik\AppData\Local\Programs\Python\Python312\Lib\site-packages\sqlalchemy\util\_concurrency_py3k.py", line 196, in greenlet_spawn
    value = await result
            ^^^^^^^^^^^^
  File "C:\Users\Manik\AppData\Local\Programs\Python\Python312\Lib\site-packages\sqlalchemy\dialects\postgresql\asyncpg.py", line 550, in _prepare_and_execute
    self._handle_exception(error)
  File "C:\Users\Manik\AppData\Local\Programs\Python\Python312\Lib\site-packages\sqlalchemy\dialects\postgresql\asyncpg.py", line 501, in _handle_exception
    self._adapt_connection._handle_exception(error)
  File "C:\Users\Manik\AppData\Local\Programs\Python\Python312\Lib\site-packages\sqlalchemy\dialects\postgresql\asyncpg.py", line 784, in _handle_exception
    raise translated_error from error
sqlalchemy.dialects.postgresql.asyncpg.AsyncAdapt_asyncpg_dbapi.ProgrammingError: <class 'asyncpg.exceptions.UndefinedColumnError'>: column users.email does not exist

The above exception was the direct cause of the following exception:

Traceback (most recent call last):
  File "C:\Users\Manik\AppData\Local\Programs\Python\Python312\Lib\site-packages\starlette\middleware\errors.py", line 165, in __call__
    await self.app(scope, receive, _send)
  File "C:\Users\Manik\AppData\Local\Programs\Python\Python312\Lib\site-packages\starlette\middleware\cors.py", line 93, in __call__
    await self.simple_response(scope, receive, send, request_headers=headers)
  File "C:\Users\Manik\AppData\Local\Programs\Python\Python312\Lib\site-packages\starlette\middleware\cors.py", line 144, in simple_response
    await self.app(scope, receive, send)
  File "C:\Users\Manik\AppData\Local\Programs\Python\Python312\Lib\site-packages\starlette\middleware\exceptions.py", line 62, in __call__
    await wrap_app_handling_exceptions(self.app, conn)(scope, receive, send)
  File "C:\Users\Manik\AppData\Local\Programs\Python\Python312\Lib\site-packages\starlette\_exception_handler.py", line 53, in wrapped_app
    raise exc
  File "C:\Users\Manik\AppData\Local\Programs\Python\Python312\Lib\site-packages\starlette\_exception_handler.py", line 42, in wrapped_app
    await app(scope, receive, sender)
  File "C:\Users\Manik\AppData\Local\Programs\Python\Python312\Lib\site-packages\starlette\routing.py", line 714, in __call__
    await self.middleware_stack(scope, receive, send)
  File "C:\Users\Manik\AppData\Local\Programs\Python\Python312\Lib\site-packages\starlette\routing.py", line 734, in app
    await route.handle(scope, receive, send)
  File "C:\Users\Manik\AppData\Local\Programs\Python\Python312\Lib\site-packages\starlette\routing.py", line 288, in handle
    await self.app(scope, receive, send)
  File "C:\Users\Manik\AppData\Local\Programs\Python\Python312\Lib\site-packages\starlette\routing.py", line 76, in app
    await wrap_app_handling_exceptions(app, request)(scope, receive, send)
  File "C:\Users\Manik\AppData\Local\Programs\Python\Python312\Lib\site-packages\starlette\_exception_handler.py", line 53, in wrapped_app
    raise exc
  File "C:\Users\Manik\AppData\Local\Programs\Python\Python312\Lib\site-packages\starlette\_exception_handler.py", line 42, in wrapped_app
    await app(scope, receive, sender)
  File "C:\Users\Manik\AppData\Local\Programs\Python\Python312\Lib\site-packages\starlette\routing.py", line 73, in app
    response = await f(request)
               ^^^^^^^^^^^^^^^^
  File "C:\Users\Manik\AppData\Local\Programs\Python\Python312\Lib\site-packages\fastapi\routing.py", line 301, in app
    raw_response = await run_endpoint_function(
                   ^^^^^^^^^^^^^^^^^^^^^^^^^^^^
  File "C:\Users\Manik\AppData\Local\Programs\Python\Python312\Lib\site-packages\fastapi\routing.py", line 212, in run_endpoint_function
    return await dependant.call(**values)
           ^^^^^^^^^^^^^^^^^^^^^^^^^^^^^^
  File "D:\chatbot_app_final\backend\main.py", line 71, in signup
    db_user = await crud.get_user_by_email(db, user.email)
              ^^^^^^^^^^^^^^^^^^^^^^^^^^^^^^^^^^^^^^^^^^^^
  File "D:\chatbot_app_final\backend\crud.py", line 37, in get_user_by_email
    result = await db.execute(select(models.User).where(models.User.email == email))
             ^^^^^^^^^^^^^^^^^^^^^^^^^^^^^^^^^^^^^^^^^^^^^^^^^^^^^^^^^^^^^^^^^^^^^^^
  File "C:\Users\Manik\AppData\Local\Programs\Python\Python312\Lib\site-packages\sqlalchemy\ext\asyncio\session.py", line 461, in execute
    result = await greenlet_spawn(
             ^^^^^^^^^^^^^^^^^^^^^
  File "C:\Users\Manik\AppData\Local\Programs\Python\Python312\Lib\site-packages\sqlalchemy\util\_concurrency_py3k.py", line 201, in greenlet_spawn
    result = context.throw(*sys.exc_info())
             ^^^^^^^^^^^^^^^^^^^^^^^^^^^^^^
  File "C:\Users\Manik\AppData\Local\Programs\Python\Python312\Lib\site-packages\sqlalchemy\orm\session.py", line 2362, in execute
    return self._execute_internal(
           ^^^^^^^^^^^^^^^^^^^^^^^
  File "C:\Users\Manik\AppData\Local\Programs\Python\Python312\Lib\site-packages\sqlalchemy\orm\session.py", line 2247, in _execute_internal
    result: Result[Any] = compile_state_cls.orm_execute_statement(
                          ^^^^^^^^^^^^^^^^^^^^^^^^^^^^^^^^^^^^^^^^
  File "C:\Users\Manik\AppData\Local\Programs\Python\Python312\Lib\site-packages\sqlalchemy\orm\context.py", line 305, in orm_execute_statement
    result = conn.execute(
             ^^^^^^^^^^^^^
  File "C:\Users\Manik\AppData\Local\Programs\Python\Python312\Lib\site-packages\sqlalchemy\engine\base.py", line 1418, in execute
    return meth(
           ^^^^^
  File "C:\Users\Manik\AppData\Local\Programs\Python\Python312\Lib\site-packages\sqlalchemy\sql\elements.py", line 515, in _execute_on_connection
    return connection._execute_clauseelement(
           ^^^^^^^^^^^^^^^^^^^^^^^^^^^^^^^^^^
  File "C:\Users\Manik\AppData\Local\Programs\Python\Python312\Lib\site-packages\sqlalchemy\engine\base.py", line 1640, in _execute_clauseelement
    ret = self._execute_context(
          ^^^^^^^^^^^^^^^^^^^^^^
  File "C:\Users\Manik\AppData\Local\Programs\Python\Python312\Lib\site-packages\sqlalchemy\engine\base.py", line 1846, in _execute_context
    return self._exec_single_context(
           ^^^^^^^^^^^^^^^^^^^^^^^^^^
  File "C:\Users\Manik\AppData\Local\Programs\Python\Python312\Lib\site-packages\sqlalchemy\engine\base.py", line 1986, in _exec_single_context
    self._handle_dbapi_exception(
  File "C:\Users\Manik\AppData\Local\Programs\Python\Python312\Lib\site-packages\sqlalchemy\engine\base.py", line 2355, in _handle_dbapi_exception
    raise sqlalchemy_exception.with_traceback(exc_info[2]) from e
  File "C:\Users\Manik\AppData\Local\Programs\Python\Python312\Lib\site-packages\sqlalchemy\engine\base.py", line 1967, in _exec_single_context
    self.dialect.do_execute(
  File "C:\Users\Manik\AppData\Local\Programs\Python\Python312\Lib\site-packages\sqlalchemy\engine\default.py", line 941, in do_execute
    cursor.execute(statement, parameters)
  File "C:\Users\Manik\AppData\Local\Programs\Python\Python312\Lib\site-packages\sqlalchemy\dialects\postgresql\asyncpg.py", line 572, in execute
    self._adapt_connection.await_(
  File "C:\Users\Manik\AppData\Local\Programs\Python\Python312\Lib\site-packages\sqlalchemy\util\_concurrency_py3k.py", line 132, in await_only
    return current.parent.switch(awaitable)  # type: ignore[no-any-return,attr-defined] # noqa: E501
           ^^^^^^^^^^^^^^^^^^^^^^^^^^^^^^^^
  File "C:\Users\Manik\AppData\Local\Programs\Python\Python312\Lib\site-packages\sqlalchemy\util\_concurrency_py3k.py", line 196, in greenlet_spawn
    value = await result
            ^^^^^^^^^^^^
  File "C:\Users\Manik\AppData\Local\Programs\Python\Python312\Lib\site-packages\sqlalchemy\dialects\postgresql\asyncpg.py", line 550, in _prepare_and_execute
    self._handle_exception(error)
  File "C:\Users\Manik\AppData\Local\Programs\Python\Python312\Lib\site-packages\sqlalchemy\dialects\postgresql\asyncpg.py", line 501, in _handle_exception
    self._adapt_connection._handle_exception(error)
  File "C:\Users\Manik\AppData\Local\Programs\Python\Python312\Lib\site-packages\sqlalchemy\dialects\postgresql\asyncpg.py", line 784, in _handle_exception
    raise translated_error from error
sqlalchemy.exc.ProgrammingError: (sqlalchemy.dialects.postgresql.asyncpg.ProgrammingError) <class 'asyncpg.exceptions.UndefinedColumnError'>: column users.email does not exist
[SQL: SELECT users.id, users.email, users.password 
FROM users 
WHERE users.email = $1::VARCHAR]
[parameters: ('mj5@gmail.com',)]
(Background on this error at: https://sqlalche.me/e/20/f405)

2025-06-30 11:54:19,602 - ERROR - Unhandled error at http://127.0.0.1:8000/signup
Traceback (most recent call last):
  File "C:\Users\Manik\AppData\Local\Programs\Python\Python312\Lib\site-packages\sqlalchemy\dialects\postgresql\asyncpg.py", line 514, in _prepare_and_execute
    prepared_stmt, attributes = await adapt_connection._prepare(
                                ^^^^^^^^^^^^^^^^^^^^^^^^^^^^^^^^
  File "C:\Users\Manik\AppData\Local\Programs\Python\Python312\Lib\site-packages\sqlalchemy\dialects\postgresql\asyncpg.py", line 760, in _prepare
    prepared_stmt = await self._connection.prepare(
                    ^^^^^^^^^^^^^^^^^^^^^^^^^^^^^^^
  File "C:\Users\Manik\AppData\Local\Programs\Python\Python312\Lib\site-packages\asyncpg\connection.py", line 635, in prepare
    return await self._prepare(
           ^^^^^^^^^^^^^^^^^^^^
  File "C:\Users\Manik\AppData\Local\Programs\Python\Python312\Lib\site-packages\asyncpg\connection.py", line 653, in _prepare
    stmt = await self._get_statement(
           ^^^^^^^^^^^^^^^^^^^^^^^^^^
  File "C:\Users\Manik\AppData\Local\Programs\Python\Python312\Lib\site-packages\asyncpg\connection.py", line 432, in _get_statement
    statement = await self._protocol.prepare(
                ^^^^^^^^^^^^^^^^^^^^^^^^^^^^^
  File "asyncpg\\protocol\\protocol.pyx", line 165, in prepare
asyncpg.exceptions.UndefinedColumnError: column users.email does not exist

The above exception was the direct cause of the following exception:

Traceback (most recent call last):
  File "C:\Users\Manik\AppData\Local\Programs\Python\Python312\Lib\site-packages\sqlalchemy\engine\base.py", line 1967, in _exec_single_context
    self.dialect.do_execute(
  File "C:\Users\Manik\AppData\Local\Programs\Python\Python312\Lib\site-packages\sqlalchemy\engine\default.py", line 941, in do_execute
    cursor.execute(statement, parameters)
  File "C:\Users\Manik\AppData\Local\Programs\Python\Python312\Lib\site-packages\sqlalchemy\dialects\postgresql\asyncpg.py", line 572, in execute
    self._adapt_connection.await_(
  File "C:\Users\Manik\AppData\Local\Programs\Python\Python312\Lib\site-packages\sqlalchemy\util\_concurrency_py3k.py", line 132, in await_only
    return current.parent.switch(awaitable)  # type: ignore[no-any-return,attr-defined] # noqa: E501
           ^^^^^^^^^^^^^^^^^^^^^^^^^^^^^^^^
  File "C:\Users\Manik\AppData\Local\Programs\Python\Python312\Lib\site-packages\sqlalchemy\util\_concurrency_py3k.py", line 196, in greenlet_spawn
    value = await result
            ^^^^^^^^^^^^
  File "C:\Users\Manik\AppData\Local\Programs\Python\Python312\Lib\site-packages\sqlalchemy\dialects\postgresql\asyncpg.py", line 550, in _prepare_and_execute
    self._handle_exception(error)
  File "C:\Users\Manik\AppData\Local\Programs\Python\Python312\Lib\site-packages\sqlalchemy\dialects\postgresql\asyncpg.py", line 501, in _handle_exception
    self._adapt_connection._handle_exception(error)
  File "C:\Users\Manik\AppData\Local\Programs\Python\Python312\Lib\site-packages\sqlalchemy\dialects\postgresql\asyncpg.py", line 784, in _handle_exception
    raise translated_error from error
sqlalchemy.dialects.postgresql.asyncpg.AsyncAdapt_asyncpg_dbapi.ProgrammingError: <class 'asyncpg.exceptions.UndefinedColumnError'>: column users.email does not exist

The above exception was the direct cause of the following exception:

Traceback (most recent call last):
  File "C:\Users\Manik\AppData\Local\Programs\Python\Python312\Lib\site-packages\starlette\middleware\errors.py", line 165, in __call__
    await self.app(scope, receive, _send)
  File "C:\Users\Manik\AppData\Local\Programs\Python\Python312\Lib\site-packages\starlette\middleware\cors.py", line 93, in __call__
    await self.simple_response(scope, receive, send, request_headers=headers)
  File "C:\Users\Manik\AppData\Local\Programs\Python\Python312\Lib\site-packages\starlette\middleware\cors.py", line 144, in simple_response
    await self.app(scope, receive, send)
  File "C:\Users\Manik\AppData\Local\Programs\Python\Python312\Lib\site-packages\starlette\middleware\exceptions.py", line 62, in __call__
    await wrap_app_handling_exceptions(self.app, conn)(scope, receive, send)
  File "C:\Users\Manik\AppData\Local\Programs\Python\Python312\Lib\site-packages\starlette\_exception_handler.py", line 53, in wrapped_app
    raise exc
  File "C:\Users\Manik\AppData\Local\Programs\Python\Python312\Lib\site-packages\starlette\_exception_handler.py", line 42, in wrapped_app
    await app(scope, receive, sender)
  File "C:\Users\Manik\AppData\Local\Programs\Python\Python312\Lib\site-packages\starlette\routing.py", line 714, in __call__
    await self.middleware_stack(scope, receive, send)
  File "C:\Users\Manik\AppData\Local\Programs\Python\Python312\Lib\site-packages\starlette\routing.py", line 734, in app
    await route.handle(scope, receive, send)
  File "C:\Users\Manik\AppData\Local\Programs\Python\Python312\Lib\site-packages\starlette\routing.py", line 288, in handle
    await self.app(scope, receive, send)
  File "C:\Users\Manik\AppData\Local\Programs\Python\Python312\Lib\site-packages\starlette\routing.py", line 76, in app
    await wrap_app_handling_exceptions(app, request)(scope, receive, send)
  File "C:\Users\Manik\AppData\Local\Programs\Python\Python312\Lib\site-packages\starlette\_exception_handler.py", line 53, in wrapped_app
    raise exc
  File "C:\Users\Manik\AppData\Local\Programs\Python\Python312\Lib\site-packages\starlette\_exception_handler.py", line 42, in wrapped_app
    await app(scope, receive, sender)
  File "C:\Users\Manik\AppData\Local\Programs\Python\Python312\Lib\site-packages\starlette\routing.py", line 73, in app
    response = await f(request)
               ^^^^^^^^^^^^^^^^
  File "C:\Users\Manik\AppData\Local\Programs\Python\Python312\Lib\site-packages\fastapi\routing.py", line 301, in app
    raw_response = await run_endpoint_function(
                   ^^^^^^^^^^^^^^^^^^^^^^^^^^^^
  File "C:\Users\Manik\AppData\Local\Programs\Python\Python312\Lib\site-packages\fastapi\routing.py", line 212, in run_endpoint_function
    return await dependant.call(**values)
           ^^^^^^^^^^^^^^^^^^^^^^^^^^^^^^
  File "D:\chatbot_app_final\backend\main.py", line 71, in signup
    db_user = await crud.get_user_by_email(db, user.email)
              ^^^^^^^^^^^^^^^^^^^^^^^^^^^^^^^^^^^^^^^^^^^^
  File "D:\chatbot_app_final\backend\crud.py", line 37, in get_user_by_email
    result = await db.execute(select(models.User).where(models.User.email == email))
             ^^^^^^^^^^^^^^^^^^^^^^^^^^^^^^^^^^^^^^^^^^^^^^^^^^^^^^^^^^^^^^^^^^^^^^^
  File "C:\Users\Manik\AppData\Local\Programs\Python\Python312\Lib\site-packages\sqlalchemy\ext\asyncio\session.py", line 461, in execute
    result = await greenlet_spawn(
             ^^^^^^^^^^^^^^^^^^^^^
  File "C:\Users\Manik\AppData\Local\Programs\Python\Python312\Lib\site-packages\sqlalchemy\util\_concurrency_py3k.py", line 201, in greenlet_spawn
    result = context.throw(*sys.exc_info())
             ^^^^^^^^^^^^^^^^^^^^^^^^^^^^^^
  File "C:\Users\Manik\AppData\Local\Programs\Python\Python312\Lib\site-packages\sqlalchemy\orm\session.py", line 2362, in execute
    return self._execute_internal(
           ^^^^^^^^^^^^^^^^^^^^^^^
  File "C:\Users\Manik\AppData\Local\Programs\Python\Python312\Lib\site-packages\sqlalchemy\orm\session.py", line 2247, in _execute_internal
    result: Result[Any] = compile_state_cls.orm_execute_statement(
                          ^^^^^^^^^^^^^^^^^^^^^^^^^^^^^^^^^^^^^^^^
  File "C:\Users\Manik\AppData\Local\Programs\Python\Python312\Lib\site-packages\sqlalchemy\orm\context.py", line 305, in orm_execute_statement
    result = conn.execute(
             ^^^^^^^^^^^^^
  File "C:\Users\Manik\AppData\Local\Programs\Python\Python312\Lib\site-packages\sqlalchemy\engine\base.py", line 1418, in execute
    return meth(
           ^^^^^
  File "C:\Users\Manik\AppData\Local\Programs\Python\Python312\Lib\site-packages\sqlalchemy\sql\elements.py", line 515, in _execute_on_connection
    return connection._execute_clauseelement(
           ^^^^^^^^^^^^^^^^^^^^^^^^^^^^^^^^^^
  File "C:\Users\Manik\AppData\Local\Programs\Python\Python312\Lib\site-packages\sqlalchemy\engine\base.py", line 1640, in _execute_clauseelement
    ret = self._execute_context(
          ^^^^^^^^^^^^^^^^^^^^^^
  File "C:\Users\Manik\AppData\Local\Programs\Python\Python312\Lib\site-packages\sqlalchemy\engine\base.py", line 1846, in _execute_context
    return self._exec_single_context(
           ^^^^^^^^^^^^^^^^^^^^^^^^^^
  File "C:\Users\Manik\AppData\Local\Programs\Python\Python312\Lib\site-packages\sqlalchemy\engine\base.py", line 1986, in _exec_single_context
    self._handle_dbapi_exception(
  File "C:\Users\Manik\AppData\Local\Programs\Python\Python312\Lib\site-packages\sqlalchemy\engine\base.py", line 2355, in _handle_dbapi_exception
    raise sqlalchemy_exception.with_traceback(exc_info[2]) from e
  File "C:\Users\Manik\AppData\Local\Programs\Python\Python312\Lib\site-packages\sqlalchemy\engine\base.py", line 1967, in _exec_single_context
    self.dialect.do_execute(
  File "C:\Users\Manik\AppData\Local\Programs\Python\Python312\Lib\site-packages\sqlalchemy\engine\default.py", line 941, in do_execute
    cursor.execute(statement, parameters)
  File "C:\Users\Manik\AppData\Local\Programs\Python\Python312\Lib\site-packages\sqlalchemy\dialects\postgresql\asyncpg.py", line 572, in execute
    self._adapt_connection.await_(
  File "C:\Users\Manik\AppData\Local\Programs\Python\Python312\Lib\site-packages\sqlalchemy\util\_concurrency_py3k.py", line 132, in await_only
    return current.parent.switch(awaitable)  # type: ignore[no-any-return,attr-defined] # noqa: E501
           ^^^^^^^^^^^^^^^^^^^^^^^^^^^^^^^^
  File "C:\Users\Manik\AppData\Local\Programs\Python\Python312\Lib\site-packages\sqlalchemy\util\_concurrency_py3k.py", line 196, in greenlet_spawn
    value = await result
            ^^^^^^^^^^^^
  File "C:\Users\Manik\AppData\Local\Programs\Python\Python312\Lib\site-packages\sqlalchemy\dialects\postgresql\asyncpg.py", line 550, in _prepare_and_execute
    self._handle_exception(error)
  File "C:\Users\Manik\AppData\Local\Programs\Python\Python312\Lib\site-packages\sqlalchemy\dialects\postgresql\asyncpg.py", line 501, in _handle_exception
    self._adapt_connection._handle_exception(error)
  File "C:\Users\Manik\AppData\Local\Programs\Python\Python312\Lib\site-packages\sqlalchemy\dialects\postgresql\asyncpg.py", line 784, in _handle_exception
    raise translated_error from error
sqlalchemy.exc.ProgrammingError: (sqlalchemy.dialects.postgresql.asyncpg.ProgrammingError) <class 'asyncpg.exceptions.UndefinedColumnError'>: column users.email does not exist
[SQL: SELECT users.id, users.email, users.password 
FROM users 
WHERE users.email = $1::VARCHAR]
[parameters: ('mj5@gmail.com',)]
(Background on this error at: https://sqlalche.me/e/20/f405)

2025-06-30 11:55:16,588 - ERROR - Unhandled error at http://127.0.0.1:8000/signup
Traceback (most recent call last):
  File "C:\Users\Manik\AppData\Local\Programs\Python\Python312\Lib\site-packages\sqlalchemy\dialects\postgresql\asyncpg.py", line 514, in _prepare_and_execute
    prepared_stmt, attributes = await adapt_connection._prepare(
                                ^^^^^^^^^^^^^^^^^^^^^^^^^^^^^^^^
  File "C:\Users\Manik\AppData\Local\Programs\Python\Python312\Lib\site-packages\sqlalchemy\dialects\postgresql\asyncpg.py", line 760, in _prepare
    prepared_stmt = await self._connection.prepare(
                    ^^^^^^^^^^^^^^^^^^^^^^^^^^^^^^^
  File "C:\Users\Manik\AppData\Local\Programs\Python\Python312\Lib\site-packages\asyncpg\connection.py", line 635, in prepare
    return await self._prepare(
           ^^^^^^^^^^^^^^^^^^^^
  File "C:\Users\Manik\AppData\Local\Programs\Python\Python312\Lib\site-packages\asyncpg\connection.py", line 653, in _prepare
    stmt = await self._get_statement(
           ^^^^^^^^^^^^^^^^^^^^^^^^^^
  File "C:\Users\Manik\AppData\Local\Programs\Python\Python312\Lib\site-packages\asyncpg\connection.py", line 432, in _get_statement
    statement = await self._protocol.prepare(
                ^^^^^^^^^^^^^^^^^^^^^^^^^^^^^
  File "asyncpg\\protocol\\protocol.pyx", line 165, in prepare
asyncpg.exceptions.UndefinedColumnError: column users.email does not exist

The above exception was the direct cause of the following exception:

Traceback (most recent call last):
  File "C:\Users\Manik\AppData\Local\Programs\Python\Python312\Lib\site-packages\sqlalchemy\engine\base.py", line 1967, in _exec_single_context
    self.dialect.do_execute(
  File "C:\Users\Manik\AppData\Local\Programs\Python\Python312\Lib\site-packages\sqlalchemy\engine\default.py", line 941, in do_execute
    cursor.execute(statement, parameters)
  File "C:\Users\Manik\AppData\Local\Programs\Python\Python312\Lib\site-packages\sqlalchemy\dialects\postgresql\asyncpg.py", line 572, in execute
    self._adapt_connection.await_(
  File "C:\Users\Manik\AppData\Local\Programs\Python\Python312\Lib\site-packages\sqlalchemy\util\_concurrency_py3k.py", line 132, in await_only
    return current.parent.switch(awaitable)  # type: ignore[no-any-return,attr-defined] # noqa: E501
           ^^^^^^^^^^^^^^^^^^^^^^^^^^^^^^^^
  File "C:\Users\Manik\AppData\Local\Programs\Python\Python312\Lib\site-packages\sqlalchemy\util\_concurrency_py3k.py", line 196, in greenlet_spawn
    value = await result
            ^^^^^^^^^^^^
  File "C:\Users\Manik\AppData\Local\Programs\Python\Python312\Lib\site-packages\sqlalchemy\dialects\postgresql\asyncpg.py", line 550, in _prepare_and_execute
    self._handle_exception(error)
  File "C:\Users\Manik\AppData\Local\Programs\Python\Python312\Lib\site-packages\sqlalchemy\dialects\postgresql\asyncpg.py", line 501, in _handle_exception
    self._adapt_connection._handle_exception(error)
  File "C:\Users\Manik\AppData\Local\Programs\Python\Python312\Lib\site-packages\sqlalchemy\dialects\postgresql\asyncpg.py", line 784, in _handle_exception
    raise translated_error from error
sqlalchemy.dialects.postgresql.asyncpg.AsyncAdapt_asyncpg_dbapi.ProgrammingError: <class 'asyncpg.exceptions.UndefinedColumnError'>: column users.email does not exist

The above exception was the direct cause of the following exception:

Traceback (most recent call last):
  File "C:\Users\Manik\AppData\Local\Programs\Python\Python312\Lib\site-packages\starlette\middleware\errors.py", line 165, in __call__
    await self.app(scope, receive, _send)
  File "C:\Users\Manik\AppData\Local\Programs\Python\Python312\Lib\site-packages\starlette\middleware\cors.py", line 93, in __call__
    await self.simple_response(scope, receive, send, request_headers=headers)
  File "C:\Users\Manik\AppData\Local\Programs\Python\Python312\Lib\site-packages\starlette\middleware\cors.py", line 144, in simple_response
    await self.app(scope, receive, send)
  File "C:\Users\Manik\AppData\Local\Programs\Python\Python312\Lib\site-packages\starlette\middleware\exceptions.py", line 62, in __call__
    await wrap_app_handling_exceptions(self.app, conn)(scope, receive, send)
  File "C:\Users\Manik\AppData\Local\Programs\Python\Python312\Lib\site-packages\starlette\_exception_handler.py", line 53, in wrapped_app
    raise exc
  File "C:\Users\Manik\AppData\Local\Programs\Python\Python312\Lib\site-packages\starlette\_exception_handler.py", line 42, in wrapped_app
    await app(scope, receive, sender)
  File "C:\Users\Manik\AppData\Local\Programs\Python\Python312\Lib\site-packages\starlette\routing.py", line 714, in __call__
    await self.middleware_stack(scope, receive, send)
  File "C:\Users\Manik\AppData\Local\Programs\Python\Python312\Lib\site-packages\starlette\routing.py", line 734, in app
    await route.handle(scope, receive, send)
  File "C:\Users\Manik\AppData\Local\Programs\Python\Python312\Lib\site-packages\starlette\routing.py", line 288, in handle
    await self.app(scope, receive, send)
  File "C:\Users\Manik\AppData\Local\Programs\Python\Python312\Lib\site-packages\starlette\routing.py", line 76, in app
    await wrap_app_handling_exceptions(app, request)(scope, receive, send)
  File "C:\Users\Manik\AppData\Local\Programs\Python\Python312\Lib\site-packages\starlette\_exception_handler.py", line 53, in wrapped_app
    raise exc
  File "C:\Users\Manik\AppData\Local\Programs\Python\Python312\Lib\site-packages\starlette\_exception_handler.py", line 42, in wrapped_app
    await app(scope, receive, sender)
  File "C:\Users\Manik\AppData\Local\Programs\Python\Python312\Lib\site-packages\starlette\routing.py", line 73, in app
    response = await f(request)
               ^^^^^^^^^^^^^^^^
  File "C:\Users\Manik\AppData\Local\Programs\Python\Python312\Lib\site-packages\fastapi\routing.py", line 301, in app
    raw_response = await run_endpoint_function(
                   ^^^^^^^^^^^^^^^^^^^^^^^^^^^^
  File "C:\Users\Manik\AppData\Local\Programs\Python\Python312\Lib\site-packages\fastapi\routing.py", line 212, in run_endpoint_function
    return await dependant.call(**values)
           ^^^^^^^^^^^^^^^^^^^^^^^^^^^^^^
  File "D:\chatbot_app_final\backend\main.py", line 71, in signup
    db_user = await crud.get_user_by_email(db, user.email)
              ^^^^^^^^^^^^^^^^^^^^^^^^^^^^^^^^^^^^^^^^^^^^
  File "D:\chatbot_app_final\backend\crud.py", line 37, in get_user_by_email
    result = await db.execute(select(models.User).where(models.User.email == email))
             ^^^^^^^^^^^^^^^^^^^^^^^^^^^^^^^^^^^^^^^^^^^^^^^^^^^^^^^^^^^^^^^^^^^^^^^
  File "C:\Users\Manik\AppData\Local\Programs\Python\Python312\Lib\site-packages\sqlalchemy\ext\asyncio\session.py", line 461, in execute
    result = await greenlet_spawn(
             ^^^^^^^^^^^^^^^^^^^^^
  File "C:\Users\Manik\AppData\Local\Programs\Python\Python312\Lib\site-packages\sqlalchemy\util\_concurrency_py3k.py", line 201, in greenlet_spawn
    result = context.throw(*sys.exc_info())
             ^^^^^^^^^^^^^^^^^^^^^^^^^^^^^^
  File "C:\Users\Manik\AppData\Local\Programs\Python\Python312\Lib\site-packages\sqlalchemy\orm\session.py", line 2362, in execute
    return self._execute_internal(
           ^^^^^^^^^^^^^^^^^^^^^^^
  File "C:\Users\Manik\AppData\Local\Programs\Python\Python312\Lib\site-packages\sqlalchemy\orm\session.py", line 2247, in _execute_internal
    result: Result[Any] = compile_state_cls.orm_execute_statement(
                          ^^^^^^^^^^^^^^^^^^^^^^^^^^^^^^^^^^^^^^^^
  File "C:\Users\Manik\AppData\Local\Programs\Python\Python312\Lib\site-packages\sqlalchemy\orm\context.py", line 305, in orm_execute_statement
    result = conn.execute(
             ^^^^^^^^^^^^^
  File "C:\Users\Manik\AppData\Local\Programs\Python\Python312\Lib\site-packages\sqlalchemy\engine\base.py", line 1418, in execute
    return meth(
           ^^^^^
  File "C:\Users\Manik\AppData\Local\Programs\Python\Python312\Lib\site-packages\sqlalchemy\sql\elements.py", line 515, in _execute_on_connection
    return connection._execute_clauseelement(
           ^^^^^^^^^^^^^^^^^^^^^^^^^^^^^^^^^^
  File "C:\Users\Manik\AppData\Local\Programs\Python\Python312\Lib\site-packages\sqlalchemy\engine\base.py", line 1640, in _execute_clauseelement
    ret = self._execute_context(
          ^^^^^^^^^^^^^^^^^^^^^^
  File "C:\Users\Manik\AppData\Local\Programs\Python\Python312\Lib\site-packages\sqlalchemy\engine\base.py", line 1846, in _execute_context
    return self._exec_single_context(
           ^^^^^^^^^^^^^^^^^^^^^^^^^^
  File "C:\Users\Manik\AppData\Local\Programs\Python\Python312\Lib\site-packages\sqlalchemy\engine\base.py", line 1986, in _exec_single_context
    self._handle_dbapi_exception(
  File "C:\Users\Manik\AppData\Local\Programs\Python\Python312\Lib\site-packages\sqlalchemy\engine\base.py", line 2355, in _handle_dbapi_exception
    raise sqlalchemy_exception.with_traceback(exc_info[2]) from e
  File "C:\Users\Manik\AppData\Local\Programs\Python\Python312\Lib\site-packages\sqlalchemy\engine\base.py", line 1967, in _exec_single_context
    self.dialect.do_execute(
  File "C:\Users\Manik\AppData\Local\Programs\Python\Python312\Lib\site-packages\sqlalchemy\engine\default.py", line 941, in do_execute
    cursor.execute(statement, parameters)
  File "C:\Users\Manik\AppData\Local\Programs\Python\Python312\Lib\site-packages\sqlalchemy\dialects\postgresql\asyncpg.py", line 572, in execute
    self._adapt_connection.await_(
  File "C:\Users\Manik\AppData\Local\Programs\Python\Python312\Lib\site-packages\sqlalchemy\util\_concurrency_py3k.py", line 132, in await_only
    return current.parent.switch(awaitable)  # type: ignore[no-any-return,attr-defined] # noqa: E501
           ^^^^^^^^^^^^^^^^^^^^^^^^^^^^^^^^
  File "C:\Users\Manik\AppData\Local\Programs\Python\Python312\Lib\site-packages\sqlalchemy\util\_concurrency_py3k.py", line 196, in greenlet_spawn
    value = await result
            ^^^^^^^^^^^^
  File "C:\Users\Manik\AppData\Local\Programs\Python\Python312\Lib\site-packages\sqlalchemy\dialects\postgresql\asyncpg.py", line 550, in _prepare_and_execute
    self._handle_exception(error)
  File "C:\Users\Manik\AppData\Local\Programs\Python\Python312\Lib\site-packages\sqlalchemy\dialects\postgresql\asyncpg.py", line 501, in _handle_exception
    self._adapt_connection._handle_exception(error)
  File "C:\Users\Manik\AppData\Local\Programs\Python\Python312\Lib\site-packages\sqlalchemy\dialects\postgresql\asyncpg.py", line 784, in _handle_exception
    raise translated_error from error
sqlalchemy.exc.ProgrammingError: (sqlalchemy.dialects.postgresql.asyncpg.ProgrammingError) <class 'asyncpg.exceptions.UndefinedColumnError'>: column users.email does not exist
[SQL: SELECT users.id, users.email, users.password 
FROM users 
WHERE users.email = $1::VARCHAR]
[parameters: ('mj5@gmail.com',)]
(Background on this error at: https://sqlalche.me/e/20/f405)

2025-06-30 11:56:28,147 - ERROR - Unhandled error at http://127.0.0.1:8000/signup
Traceback (most recent call last):
  File "C:\Users\Manik\AppData\Local\Programs\Python\Python312\Lib\site-packages\sqlalchemy\dialects\postgresql\asyncpg.py", line 514, in _prepare_and_execute
    prepared_stmt, attributes = await adapt_connection._prepare(
                                ^^^^^^^^^^^^^^^^^^^^^^^^^^^^^^^^
  File "C:\Users\Manik\AppData\Local\Programs\Python\Python312\Lib\site-packages\sqlalchemy\dialects\postgresql\asyncpg.py", line 760, in _prepare
    prepared_stmt = await self._connection.prepare(
                    ^^^^^^^^^^^^^^^^^^^^^^^^^^^^^^^
  File "C:\Users\Manik\AppData\Local\Programs\Python\Python312\Lib\site-packages\asyncpg\connection.py", line 635, in prepare
    return await self._prepare(
           ^^^^^^^^^^^^^^^^^^^^
  File "C:\Users\Manik\AppData\Local\Programs\Python\Python312\Lib\site-packages\asyncpg\connection.py", line 653, in _prepare
    stmt = await self._get_statement(
           ^^^^^^^^^^^^^^^^^^^^^^^^^^
  File "C:\Users\Manik\AppData\Local\Programs\Python\Python312\Lib\site-packages\asyncpg\connection.py", line 432, in _get_statement
    statement = await self._protocol.prepare(
                ^^^^^^^^^^^^^^^^^^^^^^^^^^^^^
  File "asyncpg\\protocol\\protocol.pyx", line 165, in prepare
asyncpg.exceptions.UndefinedColumnError: column users.email does not exist

The above exception was the direct cause of the following exception:

Traceback (most recent call last):
  File "C:\Users\Manik\AppData\Local\Programs\Python\Python312\Lib\site-packages\sqlalchemy\engine\base.py", line 1967, in _exec_single_context
    self.dialect.do_execute(
  File "C:\Users\Manik\AppData\Local\Programs\Python\Python312\Lib\site-packages\sqlalchemy\engine\default.py", line 941, in do_execute
    cursor.execute(statement, parameters)
  File "C:\Users\Manik\AppData\Local\Programs\Python\Python312\Lib\site-packages\sqlalchemy\dialects\postgresql\asyncpg.py", line 572, in execute
    self._adapt_connection.await_(
  File "C:\Users\Manik\AppData\Local\Programs\Python\Python312\Lib\site-packages\sqlalchemy\util\_concurrency_py3k.py", line 132, in await_only
    return current.parent.switch(awaitable)  # type: ignore[no-any-return,attr-defined] # noqa: E501
           ^^^^^^^^^^^^^^^^^^^^^^^^^^^^^^^^
  File "C:\Users\Manik\AppData\Local\Programs\Python\Python312\Lib\site-packages\sqlalchemy\util\_concurrency_py3k.py", line 196, in greenlet_spawn
    value = await result
            ^^^^^^^^^^^^
  File "C:\Users\Manik\AppData\Local\Programs\Python\Python312\Lib\site-packages\sqlalchemy\dialects\postgresql\asyncpg.py", line 550, in _prepare_and_execute
    self._handle_exception(error)
  File "C:\Users\Manik\AppData\Local\Programs\Python\Python312\Lib\site-packages\sqlalchemy\dialects\postgresql\asyncpg.py", line 501, in _handle_exception
    self._adapt_connection._handle_exception(error)
  File "C:\Users\Manik\AppData\Local\Programs\Python\Python312\Lib\site-packages\sqlalchemy\dialects\postgresql\asyncpg.py", line 784, in _handle_exception
    raise translated_error from error
sqlalchemy.dialects.postgresql.asyncpg.AsyncAdapt_asyncpg_dbapi.ProgrammingError: <class 'asyncpg.exceptions.UndefinedColumnError'>: column users.email does not exist

The above exception was the direct cause of the following exception:

Traceback (most recent call last):
  File "C:\Users\Manik\AppData\Local\Programs\Python\Python312\Lib\site-packages\starlette\middleware\errors.py", line 165, in __call__
    await self.app(scope, receive, _send)
  File "C:\Users\Manik\AppData\Local\Programs\Python\Python312\Lib\site-packages\starlette\middleware\cors.py", line 93, in __call__
    await self.simple_response(scope, receive, send, request_headers=headers)
  File "C:\Users\Manik\AppData\Local\Programs\Python\Python312\Lib\site-packages\starlette\middleware\cors.py", line 144, in simple_response
    await self.app(scope, receive, send)
  File "C:\Users\Manik\AppData\Local\Programs\Python\Python312\Lib\site-packages\starlette\middleware\exceptions.py", line 62, in __call__
    await wrap_app_handling_exceptions(self.app, conn)(scope, receive, send)
  File "C:\Users\Manik\AppData\Local\Programs\Python\Python312\Lib\site-packages\starlette\_exception_handler.py", line 53, in wrapped_app
    raise exc
  File "C:\Users\Manik\AppData\Local\Programs\Python\Python312\Lib\site-packages\starlette\_exception_handler.py", line 42, in wrapped_app
    await app(scope, receive, sender)
  File "C:\Users\Manik\AppData\Local\Programs\Python\Python312\Lib\site-packages\starlette\routing.py", line 714, in __call__
    await self.middleware_stack(scope, receive, send)
  File "C:\Users\Manik\AppData\Local\Programs\Python\Python312\Lib\site-packages\starlette\routing.py", line 734, in app
    await route.handle(scope, receive, send)
  File "C:\Users\Manik\AppData\Local\Programs\Python\Python312\Lib\site-packages\starlette\routing.py", line 288, in handle
    await self.app(scope, receive, send)
  File "C:\Users\Manik\AppData\Local\Programs\Python\Python312\Lib\site-packages\starlette\routing.py", line 76, in app
    await wrap_app_handling_exceptions(app, request)(scope, receive, send)
  File "C:\Users\Manik\AppData\Local\Programs\Python\Python312\Lib\site-packages\starlette\_exception_handler.py", line 53, in wrapped_app
    raise exc
  File "C:\Users\Manik\AppData\Local\Programs\Python\Python312\Lib\site-packages\starlette\_exception_handler.py", line 42, in wrapped_app
    await app(scope, receive, sender)
  File "C:\Users\Manik\AppData\Local\Programs\Python\Python312\Lib\site-packages\starlette\routing.py", line 73, in app
    response = await f(request)
               ^^^^^^^^^^^^^^^^
  File "C:\Users\Manik\AppData\Local\Programs\Python\Python312\Lib\site-packages\fastapi\routing.py", line 301, in app
    raw_response = await run_endpoint_function(
                   ^^^^^^^^^^^^^^^^^^^^^^^^^^^^
  File "C:\Users\Manik\AppData\Local\Programs\Python\Python312\Lib\site-packages\fastapi\routing.py", line 212, in run_endpoint_function
    return await dependant.call(**values)
           ^^^^^^^^^^^^^^^^^^^^^^^^^^^^^^
  File "D:\chatbot_app_final\backend\main.py", line 71, in signup
    db_user = await crud.get_user_by_email(db, user.email)
              ^^^^^^^^^^^^^^^^^^^^^^^^^^^^^^^^^^^^^^^^^^^^
  File "D:\chatbot_app_final\backend\crud.py", line 37, in get_user_by_email
    result = await db.execute(select(models.User).where(models.User.email == email))
             ^^^^^^^^^^^^^^^^^^^^^^^^^^^^^^^^^^^^^^^^^^^^^^^^^^^^^^^^^^^^^^^^^^^^^^^
  File "C:\Users\Manik\AppData\Local\Programs\Python\Python312\Lib\site-packages\sqlalchemy\ext\asyncio\session.py", line 461, in execute
    result = await greenlet_spawn(
             ^^^^^^^^^^^^^^^^^^^^^
  File "C:\Users\Manik\AppData\Local\Programs\Python\Python312\Lib\site-packages\sqlalchemy\util\_concurrency_py3k.py", line 201, in greenlet_spawn
    result = context.throw(*sys.exc_info())
             ^^^^^^^^^^^^^^^^^^^^^^^^^^^^^^
  File "C:\Users\Manik\AppData\Local\Programs\Python\Python312\Lib\site-packages\sqlalchemy\orm\session.py", line 2362, in execute
    return self._execute_internal(
           ^^^^^^^^^^^^^^^^^^^^^^^
  File "C:\Users\Manik\AppData\Local\Programs\Python\Python312\Lib\site-packages\sqlalchemy\orm\session.py", line 2247, in _execute_internal
    result: Result[Any] = compile_state_cls.orm_execute_statement(
                          ^^^^^^^^^^^^^^^^^^^^^^^^^^^^^^^^^^^^^^^^
  File "C:\Users\Manik\AppData\Local\Programs\Python\Python312\Lib\site-packages\sqlalchemy\orm\context.py", line 305, in orm_execute_statement
    result = conn.execute(
             ^^^^^^^^^^^^^
  File "C:\Users\Manik\AppData\Local\Programs\Python\Python312\Lib\site-packages\sqlalchemy\engine\base.py", line 1418, in execute
    return meth(
           ^^^^^
  File "C:\Users\Manik\AppData\Local\Programs\Python\Python312\Lib\site-packages\sqlalchemy\sql\elements.py", line 515, in _execute_on_connection
    return connection._execute_clauseelement(
           ^^^^^^^^^^^^^^^^^^^^^^^^^^^^^^^^^^
  File "C:\Users\Manik\AppData\Local\Programs\Python\Python312\Lib\site-packages\sqlalchemy\engine\base.py", line 1640, in _execute_clauseelement
    ret = self._execute_context(
          ^^^^^^^^^^^^^^^^^^^^^^
  File "C:\Users\Manik\AppData\Local\Programs\Python\Python312\Lib\site-packages\sqlalchemy\engine\base.py", line 1846, in _execute_context
    return self._exec_single_context(
           ^^^^^^^^^^^^^^^^^^^^^^^^^^
  File "C:\Users\Manik\AppData\Local\Programs\Python\Python312\Lib\site-packages\sqlalchemy\engine\base.py", line 1986, in _exec_single_context
    self._handle_dbapi_exception(
  File "C:\Users\Manik\AppData\Local\Programs\Python\Python312\Lib\site-packages\sqlalchemy\engine\base.py", line 2355, in _handle_dbapi_exception
    raise sqlalchemy_exception.with_traceback(exc_info[2]) from e
  File "C:\Users\Manik\AppData\Local\Programs\Python\Python312\Lib\site-packages\sqlalchemy\engine\base.py", line 1967, in _exec_single_context
    self.dialect.do_execute(
  File "C:\Users\Manik\AppData\Local\Programs\Python\Python312\Lib\site-packages\sqlalchemy\engine\default.py", line 941, in do_execute
    cursor.execute(statement, parameters)
  File "C:\Users\Manik\AppData\Local\Programs\Python\Python312\Lib\site-packages\sqlalchemy\dialects\postgresql\asyncpg.py", line 572, in execute
    self._adapt_connection.await_(
  File "C:\Users\Manik\AppData\Local\Programs\Python\Python312\Lib\site-packages\sqlalchemy\util\_concurrency_py3k.py", line 132, in await_only
    return current.parent.switch(awaitable)  # type: ignore[no-any-return,attr-defined] # noqa: E501
           ^^^^^^^^^^^^^^^^^^^^^^^^^^^^^^^^
  File "C:\Users\Manik\AppData\Local\Programs\Python\Python312\Lib\site-packages\sqlalchemy\util\_concurrency_py3k.py", line 196, in greenlet_spawn
    value = await result
            ^^^^^^^^^^^^
  File "C:\Users\Manik\AppData\Local\Programs\Python\Python312\Lib\site-packages\sqlalchemy\dialects\postgresql\asyncpg.py", line 550, in _prepare_and_execute
    self._handle_exception(error)
  File "C:\Users\Manik\AppData\Local\Programs\Python\Python312\Lib\site-packages\sqlalchemy\dialects\postgresql\asyncpg.py", line 501, in _handle_exception
    self._adapt_connection._handle_exception(error)
  File "C:\Users\Manik\AppData\Local\Programs\Python\Python312\Lib\site-packages\sqlalchemy\dialects\postgresql\asyncpg.py", line 784, in _handle_exception
    raise translated_error from error
sqlalchemy.exc.ProgrammingError: (sqlalchemy.dialects.postgresql.asyncpg.ProgrammingError) <class 'asyncpg.exceptions.UndefinedColumnError'>: column users.email does not exist
[SQL: SELECT users.id, users.email, users.password 
FROM users 
WHERE users.email = $1::VARCHAR]
[parameters: ('mj5@gmail.com',)]
(Background on this error at: https://sqlalche.me/e/20/f405)

2025-06-30 11:59:45,276 - ERROR - Unhandled error at http://127.0.0.1:8000/signup
Traceback (most recent call last):
  File "C:\Users\Manik\AppData\Local\Programs\Python\Python312\Lib\site-packages\sqlalchemy\dialects\postgresql\asyncpg.py", line 514, in _prepare_and_execute
    prepared_stmt, attributes = await adapt_connection._prepare(
                                ^^^^^^^^^^^^^^^^^^^^^^^^^^^^^^^^
  File "C:\Users\Manik\AppData\Local\Programs\Python\Python312\Lib\site-packages\sqlalchemy\dialects\postgresql\asyncpg.py", line 760, in _prepare
    prepared_stmt = await self._connection.prepare(
                    ^^^^^^^^^^^^^^^^^^^^^^^^^^^^^^^
  File "C:\Users\Manik\AppData\Local\Programs\Python\Python312\Lib\site-packages\asyncpg\connection.py", line 635, in prepare
    return await self._prepare(
           ^^^^^^^^^^^^^^^^^^^^
  File "C:\Users\Manik\AppData\Local\Programs\Python\Python312\Lib\site-packages\asyncpg\connection.py", line 653, in _prepare
    stmt = await self._get_statement(
           ^^^^^^^^^^^^^^^^^^^^^^^^^^
  File "C:\Users\Manik\AppData\Local\Programs\Python\Python312\Lib\site-packages\asyncpg\connection.py", line 432, in _get_statement
    statement = await self._protocol.prepare(
                ^^^^^^^^^^^^^^^^^^^^^^^^^^^^^
  File "asyncpg\\protocol\\protocol.pyx", line 165, in prepare
asyncpg.exceptions.UndefinedColumnError: column users.email does not exist

The above exception was the direct cause of the following exception:

Traceback (most recent call last):
  File "C:\Users\Manik\AppData\Local\Programs\Python\Python312\Lib\site-packages\sqlalchemy\engine\base.py", line 1967, in _exec_single_context
    self.dialect.do_execute(
  File "C:\Users\Manik\AppData\Local\Programs\Python\Python312\Lib\site-packages\sqlalchemy\engine\default.py", line 941, in do_execute
    cursor.execute(statement, parameters)
  File "C:\Users\Manik\AppData\Local\Programs\Python\Python312\Lib\site-packages\sqlalchemy\dialects\postgresql\asyncpg.py", line 572, in execute
    self._adapt_connection.await_(
  File "C:\Users\Manik\AppData\Local\Programs\Python\Python312\Lib\site-packages\sqlalchemy\util\_concurrency_py3k.py", line 132, in await_only
    return current.parent.switch(awaitable)  # type: ignore[no-any-return,attr-defined] # noqa: E501
           ^^^^^^^^^^^^^^^^^^^^^^^^^^^^^^^^
  File "C:\Users\Manik\AppData\Local\Programs\Python\Python312\Lib\site-packages\sqlalchemy\util\_concurrency_py3k.py", line 196, in greenlet_spawn
    value = await result
            ^^^^^^^^^^^^
  File "C:\Users\Manik\AppData\Local\Programs\Python\Python312\Lib\site-packages\sqlalchemy\dialects\postgresql\asyncpg.py", line 550, in _prepare_and_execute
    self._handle_exception(error)
  File "C:\Users\Manik\AppData\Local\Programs\Python\Python312\Lib\site-packages\sqlalchemy\dialects\postgresql\asyncpg.py", line 501, in _handle_exception
    self._adapt_connection._handle_exception(error)
  File "C:\Users\Manik\AppData\Local\Programs\Python\Python312\Lib\site-packages\sqlalchemy\dialects\postgresql\asyncpg.py", line 784, in _handle_exception
    raise translated_error from error
sqlalchemy.dialects.postgresql.asyncpg.AsyncAdapt_asyncpg_dbapi.ProgrammingError: <class 'asyncpg.exceptions.UndefinedColumnError'>: column users.email does not exist

The above exception was the direct cause of the following exception:

Traceback (most recent call last):
  File "C:\Users\Manik\AppData\Local\Programs\Python\Python312\Lib\site-packages\starlette\middleware\errors.py", line 165, in __call__
    await self.app(scope, receive, _send)
  File "C:\Users\Manik\AppData\Local\Programs\Python\Python312\Lib\site-packages\starlette\middleware\cors.py", line 93, in __call__
    await self.simple_response(scope, receive, send, request_headers=headers)
  File "C:\Users\Manik\AppData\Local\Programs\Python\Python312\Lib\site-packages\starlette\middleware\cors.py", line 144, in simple_response
    await self.app(scope, receive, send)
  File "C:\Users\Manik\AppData\Local\Programs\Python\Python312\Lib\site-packages\starlette\middleware\exceptions.py", line 62, in __call__
    await wrap_app_handling_exceptions(self.app, conn)(scope, receive, send)
  File "C:\Users\Manik\AppData\Local\Programs\Python\Python312\Lib\site-packages\starlette\_exception_handler.py", line 53, in wrapped_app
    raise exc
  File "C:\Users\Manik\AppData\Local\Programs\Python\Python312\Lib\site-packages\starlette\_exception_handler.py", line 42, in wrapped_app
    await app(scope, receive, sender)
  File "C:\Users\Manik\AppData\Local\Programs\Python\Python312\Lib\site-packages\starlette\routing.py", line 714, in __call__
    await self.middleware_stack(scope, receive, send)
  File "C:\Users\Manik\AppData\Local\Programs\Python\Python312\Lib\site-packages\starlette\routing.py", line 734, in app
    await route.handle(scope, receive, send)
  File "C:\Users\Manik\AppData\Local\Programs\Python\Python312\Lib\site-packages\starlette\routing.py", line 288, in handle
    await self.app(scope, receive, send)
  File "C:\Users\Manik\AppData\Local\Programs\Python\Python312\Lib\site-packages\starlette\routing.py", line 76, in app
    await wrap_app_handling_exceptions(app, request)(scope, receive, send)
  File "C:\Users\Manik\AppData\Local\Programs\Python\Python312\Lib\site-packages\starlette\_exception_handler.py", line 53, in wrapped_app
    raise exc
  File "C:\Users\Manik\AppData\Local\Programs\Python\Python312\Lib\site-packages\starlette\_exception_handler.py", line 42, in wrapped_app
    await app(scope, receive, sender)
  File "C:\Users\Manik\AppData\Local\Programs\Python\Python312\Lib\site-packages\starlette\routing.py", line 73, in app
    response = await f(request)
               ^^^^^^^^^^^^^^^^
  File "C:\Users\Manik\AppData\Local\Programs\Python\Python312\Lib\site-packages\fastapi\routing.py", line 301, in app
    raw_response = await run_endpoint_function(
                   ^^^^^^^^^^^^^^^^^^^^^^^^^^^^
  File "C:\Users\Manik\AppData\Local\Programs\Python\Python312\Lib\site-packages\fastapi\routing.py", line 212, in run_endpoint_function
    return await dependant.call(**values)
           ^^^^^^^^^^^^^^^^^^^^^^^^^^^^^^
  File "D:\chatbot_app_final\backend\main.py", line 71, in signup
    db_user = await crud.get_user_by_email(db, user.email)
              ^^^^^^^^^^^^^^^^^^^^^^^^^^^^^^^^^^^^^^^^^^^^
  File "D:\chatbot_app_final\backend\crud.py", line 37, in get_user_by_email
    result = await db.execute(select(models.User).where(models.User.email == email))
             ^^^^^^^^^^^^^^^^^^^^^^^^^^^^^^^^^^^^^^^^^^^^^^^^^^^^^^^^^^^^^^^^^^^^^^^
  File "C:\Users\Manik\AppData\Local\Programs\Python\Python312\Lib\site-packages\sqlalchemy\ext\asyncio\session.py", line 461, in execute
    result = await greenlet_spawn(
             ^^^^^^^^^^^^^^^^^^^^^
  File "C:\Users\Manik\AppData\Local\Programs\Python\Python312\Lib\site-packages\sqlalchemy\util\_concurrency_py3k.py", line 201, in greenlet_spawn
    result = context.throw(*sys.exc_info())
             ^^^^^^^^^^^^^^^^^^^^^^^^^^^^^^
  File "C:\Users\Manik\AppData\Local\Programs\Python\Python312\Lib\site-packages\sqlalchemy\orm\session.py", line 2362, in execute
    return self._execute_internal(
           ^^^^^^^^^^^^^^^^^^^^^^^
  File "C:\Users\Manik\AppData\Local\Programs\Python\Python312\Lib\site-packages\sqlalchemy\orm\session.py", line 2247, in _execute_internal
    result: Result[Any] = compile_state_cls.orm_execute_statement(
                          ^^^^^^^^^^^^^^^^^^^^^^^^^^^^^^^^^^^^^^^^
  File "C:\Users\Manik\AppData\Local\Programs\Python\Python312\Lib\site-packages\sqlalchemy\orm\context.py", line 305, in orm_execute_statement
    result = conn.execute(
             ^^^^^^^^^^^^^
  File "C:\Users\Manik\AppData\Local\Programs\Python\Python312\Lib\site-packages\sqlalchemy\engine\base.py", line 1418, in execute
    return meth(
           ^^^^^
  File "C:\Users\Manik\AppData\Local\Programs\Python\Python312\Lib\site-packages\sqlalchemy\sql\elements.py", line 515, in _execute_on_connection
    return connection._execute_clauseelement(
           ^^^^^^^^^^^^^^^^^^^^^^^^^^^^^^^^^^
  File "C:\Users\Manik\AppData\Local\Programs\Python\Python312\Lib\site-packages\sqlalchemy\engine\base.py", line 1640, in _execute_clauseelement
    ret = self._execute_context(
          ^^^^^^^^^^^^^^^^^^^^^^
  File "C:\Users\Manik\AppData\Local\Programs\Python\Python312\Lib\site-packages\sqlalchemy\engine\base.py", line 1846, in _execute_context
    return self._exec_single_context(
           ^^^^^^^^^^^^^^^^^^^^^^^^^^
  File "C:\Users\Manik\AppData\Local\Programs\Python\Python312\Lib\site-packages\sqlalchemy\engine\base.py", line 1986, in _exec_single_context
    self._handle_dbapi_exception(
  File "C:\Users\Manik\AppData\Local\Programs\Python\Python312\Lib\site-packages\sqlalchemy\engine\base.py", line 2355, in _handle_dbapi_exception
    raise sqlalchemy_exception.with_traceback(exc_info[2]) from e
  File "C:\Users\Manik\AppData\Local\Programs\Python\Python312\Lib\site-packages\sqlalchemy\engine\base.py", line 1967, in _exec_single_context
    self.dialect.do_execute(
  File "C:\Users\Manik\AppData\Local\Programs\Python\Python312\Lib\site-packages\sqlalchemy\engine\default.py", line 941, in do_execute
    cursor.execute(statement, parameters)
  File "C:\Users\Manik\AppData\Local\Programs\Python\Python312\Lib\site-packages\sqlalchemy\dialects\postgresql\asyncpg.py", line 572, in execute
    self._adapt_connection.await_(
  File "C:\Users\Manik\AppData\Local\Programs\Python\Python312\Lib\site-packages\sqlalchemy\util\_concurrency_py3k.py", line 132, in await_only
    return current.parent.switch(awaitable)  # type: ignore[no-any-return,attr-defined] # noqa: E501
           ^^^^^^^^^^^^^^^^^^^^^^^^^^^^^^^^
  File "C:\Users\Manik\AppData\Local\Programs\Python\Python312\Lib\site-packages\sqlalchemy\util\_concurrency_py3k.py", line 196, in greenlet_spawn
    value = await result
            ^^^^^^^^^^^^
  File "C:\Users\Manik\AppData\Local\Programs\Python\Python312\Lib\site-packages\sqlalchemy\dialects\postgresql\asyncpg.py", line 550, in _prepare_and_execute
    self._handle_exception(error)
  File "C:\Users\Manik\AppData\Local\Programs\Python\Python312\Lib\site-packages\sqlalchemy\dialects\postgresql\asyncpg.py", line 501, in _handle_exception
    self._adapt_connection._handle_exception(error)
  File "C:\Users\Manik\AppData\Local\Programs\Python\Python312\Lib\site-packages\sqlalchemy\dialects\postgresql\asyncpg.py", line 784, in _handle_exception
    raise translated_error from error
sqlalchemy.exc.ProgrammingError: (sqlalchemy.dialects.postgresql.asyncpg.ProgrammingError) <class 'asyncpg.exceptions.UndefinedColumnError'>: column users.email does not exist
[SQL: SELECT users.id, users.email, users.password 
FROM users 
WHERE users.email = $1::VARCHAR]
[parameters: ('mj5@gmail.com',)]
(Background on this error at: https://sqlalche.me/e/20/f405)

2025-06-30 12:01:28,945 - ERROR - Unhandled error at http://127.0.0.1:8000/signin
Traceback (most recent call last):
  File "C:\Users\Manik\AppData\Local\Programs\Python\Python312\Lib\site-packages\sqlalchemy\dialects\postgresql\asyncpg.py", line 514, in _prepare_and_execute
    prepared_stmt, attributes = await adapt_connection._prepare(
                                ^^^^^^^^^^^^^^^^^^^^^^^^^^^^^^^^
  File "C:\Users\Manik\AppData\Local\Programs\Python\Python312\Lib\site-packages\sqlalchemy\dialects\postgresql\asyncpg.py", line 760, in _prepare
    prepared_stmt = await self._connection.prepare(
                    ^^^^^^^^^^^^^^^^^^^^^^^^^^^^^^^
  File "C:\Users\Manik\AppData\Local\Programs\Python\Python312\Lib\site-packages\asyncpg\connection.py", line 635, in prepare
    return await self._prepare(
           ^^^^^^^^^^^^^^^^^^^^
  File "C:\Users\Manik\AppData\Local\Programs\Python\Python312\Lib\site-packages\asyncpg\connection.py", line 653, in _prepare
    stmt = await self._get_statement(
           ^^^^^^^^^^^^^^^^^^^^^^^^^^
  File "C:\Users\Manik\AppData\Local\Programs\Python\Python312\Lib\site-packages\asyncpg\connection.py", line 432, in _get_statement
    statement = await self._protocol.prepare(
                ^^^^^^^^^^^^^^^^^^^^^^^^^^^^^
  File "asyncpg\\protocol\\protocol.pyx", line 165, in prepare
asyncpg.exceptions.UndefinedColumnError: column users.email does not exist

The above exception was the direct cause of the following exception:

Traceback (most recent call last):
  File "C:\Users\Manik\AppData\Local\Programs\Python\Python312\Lib\site-packages\sqlalchemy\engine\base.py", line 1967, in _exec_single_context
    self.dialect.do_execute(
  File "C:\Users\Manik\AppData\Local\Programs\Python\Python312\Lib\site-packages\sqlalchemy\engine\default.py", line 941, in do_execute
    cursor.execute(statement, parameters)
  File "C:\Users\Manik\AppData\Local\Programs\Python\Python312\Lib\site-packages\sqlalchemy\dialects\postgresql\asyncpg.py", line 572, in execute
    self._adapt_connection.await_(
  File "C:\Users\Manik\AppData\Local\Programs\Python\Python312\Lib\site-packages\sqlalchemy\util\_concurrency_py3k.py", line 132, in await_only
    return current.parent.switch(awaitable)  # type: ignore[no-any-return,attr-defined] # noqa: E501
           ^^^^^^^^^^^^^^^^^^^^^^^^^^^^^^^^
  File "C:\Users\Manik\AppData\Local\Programs\Python\Python312\Lib\site-packages\sqlalchemy\util\_concurrency_py3k.py", line 196, in greenlet_spawn
    value = await result
            ^^^^^^^^^^^^
  File "C:\Users\Manik\AppData\Local\Programs\Python\Python312\Lib\site-packages\sqlalchemy\dialects\postgresql\asyncpg.py", line 550, in _prepare_and_execute
    self._handle_exception(error)
  File "C:\Users\Manik\AppData\Local\Programs\Python\Python312\Lib\site-packages\sqlalchemy\dialects\postgresql\asyncpg.py", line 501, in _handle_exception
    self._adapt_connection._handle_exception(error)
  File "C:\Users\Manik\AppData\Local\Programs\Python\Python312\Lib\site-packages\sqlalchemy\dialects\postgresql\asyncpg.py", line 784, in _handle_exception
    raise translated_error from error
sqlalchemy.dialects.postgresql.asyncpg.AsyncAdapt_asyncpg_dbapi.ProgrammingError: <class 'asyncpg.exceptions.UndefinedColumnError'>: column users.email does not exist

The above exception was the direct cause of the following exception:

Traceback (most recent call last):
  File "C:\Users\Manik\AppData\Local\Programs\Python\Python312\Lib\site-packages\starlette\middleware\errors.py", line 165, in __call__
    await self.app(scope, receive, _send)
  File "C:\Users\Manik\AppData\Local\Programs\Python\Python312\Lib\site-packages\starlette\middleware\cors.py", line 93, in __call__
    await self.simple_response(scope, receive, send, request_headers=headers)
  File "C:\Users\Manik\AppData\Local\Programs\Python\Python312\Lib\site-packages\starlette\middleware\cors.py", line 144, in simple_response
    await self.app(scope, receive, send)
  File "C:\Users\Manik\AppData\Local\Programs\Python\Python312\Lib\site-packages\starlette\middleware\exceptions.py", line 62, in __call__
    await wrap_app_handling_exceptions(self.app, conn)(scope, receive, send)
  File "C:\Users\Manik\AppData\Local\Programs\Python\Python312\Lib\site-packages\starlette\_exception_handler.py", line 53, in wrapped_app
    raise exc
  File "C:\Users\Manik\AppData\Local\Programs\Python\Python312\Lib\site-packages\starlette\_exception_handler.py", line 42, in wrapped_app
    await app(scope, receive, sender)
  File "C:\Users\Manik\AppData\Local\Programs\Python\Python312\Lib\site-packages\starlette\routing.py", line 714, in __call__
    await self.middleware_stack(scope, receive, send)
  File "C:\Users\Manik\AppData\Local\Programs\Python\Python312\Lib\site-packages\starlette\routing.py", line 734, in app
    await route.handle(scope, receive, send)
  File "C:\Users\Manik\AppData\Local\Programs\Python\Python312\Lib\site-packages\starlette\routing.py", line 288, in handle
    await self.app(scope, receive, send)
  File "C:\Users\Manik\AppData\Local\Programs\Python\Python312\Lib\site-packages\starlette\routing.py", line 76, in app
    await wrap_app_handling_exceptions(app, request)(scope, receive, send)
  File "C:\Users\Manik\AppData\Local\Programs\Python\Python312\Lib\site-packages\starlette\_exception_handler.py", line 53, in wrapped_app
    raise exc
  File "C:\Users\Manik\AppData\Local\Programs\Python\Python312\Lib\site-packages\starlette\_exception_handler.py", line 42, in wrapped_app
    await app(scope, receive, sender)
  File "C:\Users\Manik\AppData\Local\Programs\Python\Python312\Lib\site-packages\starlette\routing.py", line 73, in app
    response = await f(request)
               ^^^^^^^^^^^^^^^^
  File "C:\Users\Manik\AppData\Local\Programs\Python\Python312\Lib\site-packages\fastapi\routing.py", line 301, in app
    raw_response = await run_endpoint_function(
                   ^^^^^^^^^^^^^^^^^^^^^^^^^^^^
  File "C:\Users\Manik\AppData\Local\Programs\Python\Python312\Lib\site-packages\fastapi\routing.py", line 212, in run_endpoint_function
    return await dependant.call(**values)
           ^^^^^^^^^^^^^^^^^^^^^^^^^^^^^^
  File "D:\chatbot_app_final\backend\main.py", line 80, in signin
    db_user = await crud.get_user_by_email(db, user.email)
              ^^^^^^^^^^^^^^^^^^^^^^^^^^^^^^^^^^^^^^^^^^^^
  File "D:\chatbot_app_final\backend\crud.py", line 37, in get_user_by_email
    result = await db.execute(select(models.User).where(models.User.email == email))
             ^^^^^^^^^^^^^^^^^^^^^^^^^^^^^^^^^^^^^^^^^^^^^^^^^^^^^^^^^^^^^^^^^^^^^^^
  File "C:\Users\Manik\AppData\Local\Programs\Python\Python312\Lib\site-packages\sqlalchemy\ext\asyncio\session.py", line 461, in execute
    result = await greenlet_spawn(
             ^^^^^^^^^^^^^^^^^^^^^
  File "C:\Users\Manik\AppData\Local\Programs\Python\Python312\Lib\site-packages\sqlalchemy\util\_concurrency_py3k.py", line 201, in greenlet_spawn
    result = context.throw(*sys.exc_info())
             ^^^^^^^^^^^^^^^^^^^^^^^^^^^^^^
  File "C:\Users\Manik\AppData\Local\Programs\Python\Python312\Lib\site-packages\sqlalchemy\orm\session.py", line 2362, in execute
    return self._execute_internal(
           ^^^^^^^^^^^^^^^^^^^^^^^
  File "C:\Users\Manik\AppData\Local\Programs\Python\Python312\Lib\site-packages\sqlalchemy\orm\session.py", line 2247, in _execute_internal
    result: Result[Any] = compile_state_cls.orm_execute_statement(
                          ^^^^^^^^^^^^^^^^^^^^^^^^^^^^^^^^^^^^^^^^
  File "C:\Users\Manik\AppData\Local\Programs\Python\Python312\Lib\site-packages\sqlalchemy\orm\context.py", line 305, in orm_execute_statement
    result = conn.execute(
             ^^^^^^^^^^^^^
  File "C:\Users\Manik\AppData\Local\Programs\Python\Python312\Lib\site-packages\sqlalchemy\engine\base.py", line 1418, in execute
    return meth(
           ^^^^^
  File "C:\Users\Manik\AppData\Local\Programs\Python\Python312\Lib\site-packages\sqlalchemy\sql\elements.py", line 515, in _execute_on_connection
    return connection._execute_clauseelement(
           ^^^^^^^^^^^^^^^^^^^^^^^^^^^^^^^^^^
  File "C:\Users\Manik\AppData\Local\Programs\Python\Python312\Lib\site-packages\sqlalchemy\engine\base.py", line 1640, in _execute_clauseelement
    ret = self._execute_context(
          ^^^^^^^^^^^^^^^^^^^^^^
  File "C:\Users\Manik\AppData\Local\Programs\Python\Python312\Lib\site-packages\sqlalchemy\engine\base.py", line 1846, in _execute_context
    return self._exec_single_context(
           ^^^^^^^^^^^^^^^^^^^^^^^^^^
  File "C:\Users\Manik\AppData\Local\Programs\Python\Python312\Lib\site-packages\sqlalchemy\engine\base.py", line 1986, in _exec_single_context
    self._handle_dbapi_exception(
  File "C:\Users\Manik\AppData\Local\Programs\Python\Python312\Lib\site-packages\sqlalchemy\engine\base.py", line 2355, in _handle_dbapi_exception
    raise sqlalchemy_exception.with_traceback(exc_info[2]) from e
  File "C:\Users\Manik\AppData\Local\Programs\Python\Python312\Lib\site-packages\sqlalchemy\engine\base.py", line 1967, in _exec_single_context
    self.dialect.do_execute(
  File "C:\Users\Manik\AppData\Local\Programs\Python\Python312\Lib\site-packages\sqlalchemy\engine\default.py", line 941, in do_execute
    cursor.execute(statement, parameters)
  File "C:\Users\Manik\AppData\Local\Programs\Python\Python312\Lib\site-packages\sqlalchemy\dialects\postgresql\asyncpg.py", line 572, in execute
    self._adapt_connection.await_(
  File "C:\Users\Manik\AppData\Local\Programs\Python\Python312\Lib\site-packages\sqlalchemy\util\_concurrency_py3k.py", line 132, in await_only
    return current.parent.switch(awaitable)  # type: ignore[no-any-return,attr-defined] # noqa: E501
           ^^^^^^^^^^^^^^^^^^^^^^^^^^^^^^^^
  File "C:\Users\Manik\AppData\Local\Programs\Python\Python312\Lib\site-packages\sqlalchemy\util\_concurrency_py3k.py", line 196, in greenlet_spawn
    value = await result
            ^^^^^^^^^^^^
  File "C:\Users\Manik\AppData\Local\Programs\Python\Python312\Lib\site-packages\sqlalchemy\dialects\postgresql\asyncpg.py", line 550, in _prepare_and_execute
    self._handle_exception(error)
  File "C:\Users\Manik\AppData\Local\Programs\Python\Python312\Lib\site-packages\sqlalchemy\dialects\postgresql\asyncpg.py", line 501, in _handle_exception
    self._adapt_connection._handle_exception(error)
  File "C:\Users\Manik\AppData\Local\Programs\Python\Python312\Lib\site-packages\sqlalchemy\dialects\postgresql\asyncpg.py", line 784, in _handle_exception
    raise translated_error from error
sqlalchemy.exc.ProgrammingError: (sqlalchemy.dialects.postgresql.asyncpg.ProgrammingError) <class 'asyncpg.exceptions.UndefinedColumnError'>: column users.email does not exist
[SQL: SELECT users.id, users.email, users.password 
FROM users 
WHERE users.email = $1::VARCHAR]
[parameters: ('hi@gmail.com',)]
(Background on this error at: https://sqlalche.me/e/20/f405)

2025-06-30 12:02:31,201 - ERROR - Unhandled error at http://127.0.0.1:8000/signup
Traceback (most recent call last):
  File "C:\Users\Manik\AppData\Local\Programs\Python\Python312\Lib\site-packages\sqlalchemy\dialects\postgresql\asyncpg.py", line 514, in _prepare_and_execute
    prepared_stmt, attributes = await adapt_connection._prepare(
                                ^^^^^^^^^^^^^^^^^^^^^^^^^^^^^^^^
  File "C:\Users\Manik\AppData\Local\Programs\Python\Python312\Lib\site-packages\sqlalchemy\dialects\postgresql\asyncpg.py", line 760, in _prepare
    prepared_stmt = await self._connection.prepare(
                    ^^^^^^^^^^^^^^^^^^^^^^^^^^^^^^^
  File "C:\Users\Manik\AppData\Local\Programs\Python\Python312\Lib\site-packages\asyncpg\connection.py", line 635, in prepare
    return await self._prepare(
           ^^^^^^^^^^^^^^^^^^^^
  File "C:\Users\Manik\AppData\Local\Programs\Python\Python312\Lib\site-packages\asyncpg\connection.py", line 653, in _prepare
    stmt = await self._get_statement(
           ^^^^^^^^^^^^^^^^^^^^^^^^^^
  File "C:\Users\Manik\AppData\Local\Programs\Python\Python312\Lib\site-packages\asyncpg\connection.py", line 432, in _get_statement
    statement = await self._protocol.prepare(
                ^^^^^^^^^^^^^^^^^^^^^^^^^^^^^
  File "asyncpg\\protocol\\protocol.pyx", line 165, in prepare
asyncpg.exceptions.UndefinedColumnError: column users.email does not exist

The above exception was the direct cause of the following exception:

Traceback (most recent call last):
  File "C:\Users\Manik\AppData\Local\Programs\Python\Python312\Lib\site-packages\sqlalchemy\engine\base.py", line 1967, in _exec_single_context
    self.dialect.do_execute(
  File "C:\Users\Manik\AppData\Local\Programs\Python\Python312\Lib\site-packages\sqlalchemy\engine\default.py", line 941, in do_execute
    cursor.execute(statement, parameters)
  File "C:\Users\Manik\AppData\Local\Programs\Python\Python312\Lib\site-packages\sqlalchemy\dialects\postgresql\asyncpg.py", line 572, in execute
    self._adapt_connection.await_(
  File "C:\Users\Manik\AppData\Local\Programs\Python\Python312\Lib\site-packages\sqlalchemy\util\_concurrency_py3k.py", line 132, in await_only
    return current.parent.switch(awaitable)  # type: ignore[no-any-return,attr-defined] # noqa: E501
           ^^^^^^^^^^^^^^^^^^^^^^^^^^^^^^^^
  File "C:\Users\Manik\AppData\Local\Programs\Python\Python312\Lib\site-packages\sqlalchemy\util\_concurrency_py3k.py", line 196, in greenlet_spawn
    value = await result
            ^^^^^^^^^^^^
  File "C:\Users\Manik\AppData\Local\Programs\Python\Python312\Lib\site-packages\sqlalchemy\dialects\postgresql\asyncpg.py", line 550, in _prepare_and_execute
    self._handle_exception(error)
  File "C:\Users\Manik\AppData\Local\Programs\Python\Python312\Lib\site-packages\sqlalchemy\dialects\postgresql\asyncpg.py", line 501, in _handle_exception
    self._adapt_connection._handle_exception(error)
  File "C:\Users\Manik\AppData\Local\Programs\Python\Python312\Lib\site-packages\sqlalchemy\dialects\postgresql\asyncpg.py", line 784, in _handle_exception
    raise translated_error from error
sqlalchemy.dialects.postgresql.asyncpg.AsyncAdapt_asyncpg_dbapi.ProgrammingError: <class 'asyncpg.exceptions.UndefinedColumnError'>: column users.email does not exist

The above exception was the direct cause of the following exception:

Traceback (most recent call last):
  File "C:\Users\Manik\AppData\Local\Programs\Python\Python312\Lib\site-packages\starlette\middleware\errors.py", line 165, in __call__
    await self.app(scope, receive, _send)
  File "C:\Users\Manik\AppData\Local\Programs\Python\Python312\Lib\site-packages\starlette\middleware\cors.py", line 93, in __call__
    await self.simple_response(scope, receive, send, request_headers=headers)
  File "C:\Users\Manik\AppData\Local\Programs\Python\Python312\Lib\site-packages\starlette\middleware\cors.py", line 144, in simple_response
    await self.app(scope, receive, send)
  File "C:\Users\Manik\AppData\Local\Programs\Python\Python312\Lib\site-packages\starlette\middleware\exceptions.py", line 62, in __call__
    await wrap_app_handling_exceptions(self.app, conn)(scope, receive, send)
  File "C:\Users\Manik\AppData\Local\Programs\Python\Python312\Lib\site-packages\starlette\_exception_handler.py", line 53, in wrapped_app
    raise exc
  File "C:\Users\Manik\AppData\Local\Programs\Python\Python312\Lib\site-packages\starlette\_exception_handler.py", line 42, in wrapped_app
    await app(scope, receive, sender)
  File "C:\Users\Manik\AppData\Local\Programs\Python\Python312\Lib\site-packages\starlette\routing.py", line 714, in __call__
    await self.middleware_stack(scope, receive, send)
  File "C:\Users\Manik\AppData\Local\Programs\Python\Python312\Lib\site-packages\starlette\routing.py", line 734, in app
    await route.handle(scope, receive, send)
  File "C:\Users\Manik\AppData\Local\Programs\Python\Python312\Lib\site-packages\starlette\routing.py", line 288, in handle
    await self.app(scope, receive, send)
  File "C:\Users\Manik\AppData\Local\Programs\Python\Python312\Lib\site-packages\starlette\routing.py", line 76, in app
    await wrap_app_handling_exceptions(app, request)(scope, receive, send)
  File "C:\Users\Manik\AppData\Local\Programs\Python\Python312\Lib\site-packages\starlette\_exception_handler.py", line 53, in wrapped_app
    raise exc
  File "C:\Users\Manik\AppData\Local\Programs\Python\Python312\Lib\site-packages\starlette\_exception_handler.py", line 42, in wrapped_app
    await app(scope, receive, sender)
  File "C:\Users\Manik\AppData\Local\Programs\Python\Python312\Lib\site-packages\starlette\routing.py", line 73, in app
    response = await f(request)
               ^^^^^^^^^^^^^^^^
  File "C:\Users\Manik\AppData\Local\Programs\Python\Python312\Lib\site-packages\fastapi\routing.py", line 301, in app
    raw_response = await run_endpoint_function(
                   ^^^^^^^^^^^^^^^^^^^^^^^^^^^^
  File "C:\Users\Manik\AppData\Local\Programs\Python\Python312\Lib\site-packages\fastapi\routing.py", line 212, in run_endpoint_function
    return await dependant.call(**values)
           ^^^^^^^^^^^^^^^^^^^^^^^^^^^^^^
  File "D:\chatbot_app_final\backend\main.py", line 71, in signup
    db_user = await crud.get_user_by_email(db, user.email)
              ^^^^^^^^^^^^^^^^^^^^^^^^^^^^^^^^^^^^^^^^^^^^
  File "D:\chatbot_app_final\backend\crud.py", line 37, in get_user_by_email
    result = await db.execute(select(models.User).where(models.User.email == email))
             ^^^^^^^^^^^^^^^^^^^^^^^^^^^^^^^^^^^^^^^^^^^^^^^^^^^^^^^^^^^^^^^^^^^^^^^
  File "C:\Users\Manik\AppData\Local\Programs\Python\Python312\Lib\site-packages\sqlalchemy\ext\asyncio\session.py", line 461, in execute
    result = await greenlet_spawn(
             ^^^^^^^^^^^^^^^^^^^^^
  File "C:\Users\Manik\AppData\Local\Programs\Python\Python312\Lib\site-packages\sqlalchemy\util\_concurrency_py3k.py", line 201, in greenlet_spawn
    result = context.throw(*sys.exc_info())
             ^^^^^^^^^^^^^^^^^^^^^^^^^^^^^^
  File "C:\Users\Manik\AppData\Local\Programs\Python\Python312\Lib\site-packages\sqlalchemy\orm\session.py", line 2362, in execute
    return self._execute_internal(
           ^^^^^^^^^^^^^^^^^^^^^^^
  File "C:\Users\Manik\AppData\Local\Programs\Python\Python312\Lib\site-packages\sqlalchemy\orm\session.py", line 2247, in _execute_internal
    result: Result[Any] = compile_state_cls.orm_execute_statement(
                          ^^^^^^^^^^^^^^^^^^^^^^^^^^^^^^^^^^^^^^^^
  File "C:\Users\Manik\AppData\Local\Programs\Python\Python312\Lib\site-packages\sqlalchemy\orm\context.py", line 305, in orm_execute_statement
    result = conn.execute(
             ^^^^^^^^^^^^^
  File "C:\Users\Manik\AppData\Local\Programs\Python\Python312\Lib\site-packages\sqlalchemy\engine\base.py", line 1418, in execute
    return meth(
           ^^^^^
  File "C:\Users\Manik\AppData\Local\Programs\Python\Python312\Lib\site-packages\sqlalchemy\sql\elements.py", line 515, in _execute_on_connection
    return connection._execute_clauseelement(
           ^^^^^^^^^^^^^^^^^^^^^^^^^^^^^^^^^^
  File "C:\Users\Manik\AppData\Local\Programs\Python\Python312\Lib\site-packages\sqlalchemy\engine\base.py", line 1640, in _execute_clauseelement
    ret = self._execute_context(
          ^^^^^^^^^^^^^^^^^^^^^^
  File "C:\Users\Manik\AppData\Local\Programs\Python\Python312\Lib\site-packages\sqlalchemy\engine\base.py", line 1846, in _execute_context
    return self._exec_single_context(
           ^^^^^^^^^^^^^^^^^^^^^^^^^^
  File "C:\Users\Manik\AppData\Local\Programs\Python\Python312\Lib\site-packages\sqlalchemy\engine\base.py", line 1986, in _exec_single_context
    self._handle_dbapi_exception(
  File "C:\Users\Manik\AppData\Local\Programs\Python\Python312\Lib\site-packages\sqlalchemy\engine\base.py", line 2355, in _handle_dbapi_exception
    raise sqlalchemy_exception.with_traceback(exc_info[2]) from e
  File "C:\Users\Manik\AppData\Local\Programs\Python\Python312\Lib\site-packages\sqlalchemy\engine\base.py", line 1967, in _exec_single_context
    self.dialect.do_execute(
  File "C:\Users\Manik\AppData\Local\Programs\Python\Python312\Lib\site-packages\sqlalchemy\engine\default.py", line 941, in do_execute
    cursor.execute(statement, parameters)
  File "C:\Users\Manik\AppData\Local\Programs\Python\Python312\Lib\site-packages\sqlalchemy\dialects\postgresql\asyncpg.py", line 572, in execute
    self._adapt_connection.await_(
  File "C:\Users\Manik\AppData\Local\Programs\Python\Python312\Lib\site-packages\sqlalchemy\util\_concurrency_py3k.py", line 132, in await_only
    return current.parent.switch(awaitable)  # type: ignore[no-any-return,attr-defined] # noqa: E501
           ^^^^^^^^^^^^^^^^^^^^^^^^^^^^^^^^
  File "C:\Users\Manik\AppData\Local\Programs\Python\Python312\Lib\site-packages\sqlalchemy\util\_concurrency_py3k.py", line 196, in greenlet_spawn
    value = await result
            ^^^^^^^^^^^^
  File "C:\Users\Manik\AppData\Local\Programs\Python\Python312\Lib\site-packages\sqlalchemy\dialects\postgresql\asyncpg.py", line 550, in _prepare_and_execute
    self._handle_exception(error)
  File "C:\Users\Manik\AppData\Local\Programs\Python\Python312\Lib\site-packages\sqlalchemy\dialects\postgresql\asyncpg.py", line 501, in _handle_exception
    self._adapt_connection._handle_exception(error)
  File "C:\Users\Manik\AppData\Local\Programs\Python\Python312\Lib\site-packages\sqlalchemy\dialects\postgresql\asyncpg.py", line 784, in _handle_exception
    raise translated_error from error
sqlalchemy.exc.ProgrammingError: (sqlalchemy.dialects.postgresql.asyncpg.ProgrammingError) <class 'asyncpg.exceptions.UndefinedColumnError'>: column users.email does not exist
[SQL: SELECT users.id, users.email, users.password 
FROM users 
WHERE users.email = $1::VARCHAR]
[parameters: ('hi@gmail.com',)]
(Background on this error at: https://sqlalche.me/e/20/f405)

